Workbook

Sheet Noviembre 2022
A1: Control Financiero — Noviembre 2022
A3: INGRESOS DEL MES
A4: Concepto | B4: Importe (€) | C4: Quién | D4: Notas
A5: Nómina Emmanuel | C5: Emmanuel | D5: ← Escribe aquí el día 1
A6: Nómina esposa | C6: Esposa | D6: ← Escribe aquí el día 1
A7: TOTAL INGRESOS | B7: =SUM(B5:B6) -> 0
A9: GASTOS DEL MES
A10: Concepto | B10: Importe (€) | C10: Quién | D10: Notas
A11: Credit Andorra 6/24 | B11: 223.65 | C11: Familia
A12: Viamoda | B12: 44.6 | C12: Familia
A13: Parking | B13: 71.5 | C13: Familia
A14: Trastero | B14: 31.5 | C14: Familia
A15: Arriendo Piso | B15: 811.5 | C15: Familia
A16: Viaje Shamir 5/10 | B16: 110.14 | C16: Familia
A17: Dacia Pyrennes 17/60 | B17: 230.25 | C17: Familia
A18: Ahorro niños | B18: 60 | C18: Familia
A19: Baja seguro | B19: 19.63 | C19: Familia
A20: Baja seguro 2 | B20: 24.44 | C20: Familia
A21: Credit Vida Salud | B21: 84.99 | C21: Familia
A22: Carroi 2/4 | B22: 50 | C22: Familia
... A34: SAAS comedor | B34: 29.63 | C34: Familia
A40: TOTAL GASTOS | B40: =SUM(B11:B39) -> 3087.37
A42: RESUMEN DEL MES
A43: Total ingresos | B43: =B7 -> 0
A44: Total gastos | B44: =B40 -> 3087.37
A45: AHORRO DEL MES | B45: =B43-B44 -> -3087.37

Sheet Diciembre 2022
A1: Control Financiero — Diciembre 2022
A3: INGRESOS DEL MES
A4: Concepto | B4: Importe (€) | C4: Quién | D4: Notas
A5: Nómina Emmanuel | C5: Emmanuel | D5: ← Escribe aquí el día 1
A6: Nómina esposa | C6: Esposa | D6: ← Escribe aquí el día 1
A7: TOTAL INGRESOS | B7: =SUM(B5:B6) -> 0
A9: GASTOS DEL MES
A10: Concepto | B10: Importe (€) | C10: Quién | D10: Notas
A11: Credit Andorra 7/24 | B11: 233.65 | C11: Familia
A12: Viamoda | B12: 34.44 | C12: Familia
A13: Parking | B13: 71.5 | C13: Familia
A14: Trastero | B14: 31.5 | C14: Familia
A15: Arriendo Piso | B15: 811.5 | C15: Familia
A16: Viaje Shamir 6/10 | B16: 110.14 | C16: Familia
A17: Dacia 18/60 | B17: 230.25 | C17: Familia
A18: Ahorro niños | B18: 60 | C18: Familia
A19: Baja seguro | B19: 19.63 | C19: Familia
A20: Baja seguro 2 | B20: 24.44 | C20: Familia
A21: Bacredit Salud | B21: 84.44 | C21: Familia
A22: Carroi 3/4 | B22: 50 | C22: Familia
... A31: Seguro Piso 6 meses | B31: 47.28 | C31: Familia
A37: TOTAL GASTOS | B37: =SUM(B11:B36) -> 2690.48
A39: RESUMEN DEL MES
A40: Total ingresos | B40: =B7 -> 0
A41: Total gastos | B41: =B37 -> 2690.48
A42: AHORRO DEL MES | B42: =B40-B41 -> -2690.48

Sheet Enero 2023
A1: Control Financiero — Enero 2023
A3: INGRESOS DEL MES
A4: Concepto | B4: Importe (€) | C4: Quién | D4: Notas
A5: Nómina Emmanuel | C5: Emmanuel | D5: ← Escribe aquí el día 1
A6: Nómina esposa | C6: Esposa | D6: ← Escribe aquí el día 1
A7: TOTAL INGRESOS | B7: =SUM(B5:B6) -> 0
A9: GASTOS DEL MES
A10: Concepto | B10: Importe (€) | C10: Quién | D10: Notas
A11: Credit Andorra 8/24 | B11: 233.65 | C11: Familia
A12: Pyrenne iPhone 14 1/24 | B12: 106.88 | C12: Familia
A13: Pyrenne | B13: 31.98 | C13: Familia
A14: Pyrenne | B14: 74.06 | C14: Familia
A15: Pyrenne | B15: 95.18 | C15: Familia
A16: Parking | B16: 71.5 | C16: Familia
A17: Trastero | B17: 31.5 | C17: Familia
A18: Arriendo Piso | B18: 811.5 | C18: Familia
A19: Dacia 18/60 | B19: 230.25 | C19: Familia
A20: Ahorro niños | B20: 60 | C20: Familia
A21: Baja seguro | B21: 19.63 | C21: Familia
A22: Baja seguro 2 | B22: 24.44 | C22: Familia
... A35: Seguro escolar anual | B35: 14.2 | C35: Familia
A36: Netflix | B36: 14.27 | C36: Familia | D36: 28/12/22-31/01/23
A37: Hospital comedor | B37: 23.04 | C37: Familia
A43: TOTAL GASTOS | B43: =SUM(B11:B42) -> 3090.12
A45: RESUMEN DEL MES
A46: Total ingresos | B46: =B7 -> 0
A47: Total gastos | B47: =B43 -> 3090.12
A48: AHORRO DEL MES | B48: =B46-B47 -> -3090.12

Sheet Febrero 2023
A1: Control Financiero — Febrero 2023
A3: INGRESOS DEL MES
A4: Concepto | B4: Importe (€) | C4: Quién | D4: Notas
A5: Nómina Emmanuel | C5: Emmanuel | D5: ← Escribe aquí el día 1
A6: Nómina esposa | C6: Esposa | D6: ← Escribe aquí el día 1
A7: TOTAL INGRESOS | B7: =SUM(B5:B6) -> 0
A9: GASTOS DEL MES
A10: Concepto | B10: Importe (€) | C10: Quién | D10: Notas
A11: Credit Andorra 9/24 | B11: 233.65 | C11: Familia
A12: iPhone 14 2/24 | B12: 62.43 | C12: Emmanuel
A13: Dacia 19/60 | B13: 230.25 | C13: Familia
A14: Arriendo 2% | B14: 843.5 | C14: Familia
A15: Trastero 7% | B15: 35.76 | C15: Familia
A16: Parking | B16: 81.44 | C16: Familia
A17: Ahorro niños | B17: 60 | C17: Familia
A18: Ahorro jubilación | B18: 60 | C18: Familia
A19: Robotica + Ludoteca | B19: 85.3 | C19: Familia
A20: Cantina | B20: 162 | C20: Familia
A21: Telecom Andorra | B21: 99 | C21: Familia
A22: My Pyri | B22: 271.77 | C22: Emmanuel
... A34: Andorra 2000 | B34: 46.02 | C34: Familia
A35: CASS 5/12 no se pagó | B35: 0 | C35: Familia | D35: no pagado
A36: Colegio Enfermería | B36: 47.03 | C36: Esposa
A37: Póliza Dacia 1/4 | B37: 140.72 | C37: Familia
A38: Comida hospital | B38: 19.75 | C38: Familia
A44: TOTAL GASTOS | B44: =SUM(B11:B43) -> 3206.23
A46: RESUMEN DEL MES
A47: Total ingresos | B47: =B7 -> 0
A48: Total gastos | B48: =B44 -> 3206.23
A49: AHORRO DEL MES | B49: =B47-B48 -> -3206.23

Sheet Marzo 2023
A1: Control Financiero — Marzo 2023
A3: INGRESOS DEL MES
A4: Concepto | B4: Importe (€) | C4: Quién | D4: Notas
A5: Nómina Emmanuel | C5: Emmanuel | D5: ← Escribe aquí el día 1
A6: Nómina esposa | C6: Esposa | D6: ← Escribe aquí el día 1
A7: TOTAL INGRESOS | B7: =SUM(B5:B6) -> 0
A9: GASTOS DEL MES
A10: Concepto | B10: Importe (€) | C10: Quién | D10: Notas
A11: Foc i lloc 2023 | B11: 53.82 | C11: Familia
A12: Credit Andorra 10/24 | B12: 233.65 | C12: Familia
A13: Pyrennes HP 8/20 | B13: 78.18 | C13: Emmanuel
A14: Pyrennes iPhone 3/24 | B14: 62.43 | C14: Emmanuel
A15: Pyrennes Dacia 20/60 | B15: 230.25 | C15: Familia
A16: Pyrennes moto 1/24 | B16: 27.1 | C16: Emmanuel
A17: Pyrennes PS5 1/24 | B17: 69.8 | C17: Familia
A18: Arriendo Piso | B18: 827.5 | C18: Familia
A19: Parking | B19: 76.4 | C19: Familia
A20: Trastero | B20: 33.6 | C20: Familia
A21: Ahorro niños | B21: 60 | C21: Familia
A22: Jubilación -falta 30 | B22: 60 | C22: Familia
... A31: Robotica + Ludoteca Emmanuel | B31: 80.2 | C31: Emmanuel
A32: CASS 6/12 no se pagó | B32: 0 | C32: Familia | D32: no pagado
A33: Viamoda | B33: 84 | C33: Familia
A34: FEDA | B34: 113.4 | C34: Familia
A35: Andorra 2000 Emmanuel | B35: 212.61 | C35: Emmanuel
A36: Andorra 2000 Elisel | B36: 90.27 | C36: Esposa
A37: Tarjeta Pyrennes Emmanuel | B37: 175.61 | C37: Emmanuel
A38: Impuesto Gover Dacia | B38: 24 | C38: Familia
A39: Ludoteca Emiliano | B39: 17.2 | C39: Familia
A45: TOTAL GASTOS | B45: =SUM(B11:B44) -> 3186.62
A47: RESUMEN DEL MES
A48: Total ingresos | B48: =B7 -> 0
A49: Total gastos | B49: =B45 -> 3186.62
A50: AHORRO DEL MES | B50: =B48-B49 -> -3186.62

Sheet Abril 2023
A1: Control Financiero — Abril 2023
A3: INGRESOS DEL MES
A4: Concepto | B4: Importe (€) | C4: Quién | D4: Notas
A5: Nómina Emmanuel | C5: Emmanuel | D5: ← Escribe aquí el día 1
A6: Nómina esposa | C6: Esposa | D6: ← Escribe aquí el día 1
A7: TOTAL INGRESOS | B7: =SUM(B5:B6) -> 0
A9: GASTOS DEL MES
A10: Concepto | B10: Importe (€) | C10: Quién | D10: Notas
A11: Credit Andorra 11/24 | B11: 233.6 | C11: Familia
A12: Pyrennes HP 9/20 | B12: 78.18 | C12: Emmanuel
A13: Pyrennes iPhone 4/24 | B13: 62.43 | C13: Emmanuel
A14: Pyrenne Dacia 21/60 | B14: 230.25 | C14: Familia
A15: Pyrenne Moto 2/24 | B15: 111.98 | C15: Emmanuel
A16: Pyrenne PS5 2/24 | B16: 41.79 | C16: Familia
A17: Arriendo Piso | B17: 827.5 | C17: Familia
A18: Parking | B18: 76.4 | C18: Familia
A19: Trastero | B19: 33.6 | C19: Familia
A20: Ahorro niños Emmanuel | B20: 60 | C20: Emmanuel
A21: Ahorro Jubilación Emmanuel | B21: 60 | C21: Emmanuel
A22: Cantina | B22: 170 | C22: Familia
... A38: Hospital comida | B38: 13.89 | C38: Familia
A44: TOTAL GASTOS | B44: =SUM(B11:B43) -> 3196.99
A46: RESUMEN DEL MES
A47: Total ingresos | B47: =B7 -> 0
A48: Total gastos | B48: =B44 -> 3196.99
A49: AHORRO DEL MES | B49: =B47-B48 -> -3196.99

Sheet Mayo 2023
A1: Control Financiero — Mayo 2023
A3: INGRESOS DEL MES
A4: Concepto | B4: Importe (€) | C4: Quién | D4: Notas
A5: Nómina Emmanuel | C5: Emmanuel | D5: ← Escribe aquí el día 1
A6: Nómina esposa | C6: Esposa | D6: ← Escribe aquí el día 1
A7: TOTAL INGRESOS | B7: =SUM(B5:B6) -> 0
A9: GASTOS DEL MES
A10: Concepto | B10: Importe (€) | C10: Quién | D10: Notas
A11: Credit Andorra 12/24 | B11: 233.6 | C11: Familia
A12: Pyrennes HP 10/20 | B12: 78.18 | C12: Emmanuel
A13: Pyrennes iPhone 5/24 | B13: 62.43 | C13: Emmanuel
A14: Pyrenne Dacia 22/60 | B14: 230.25 | C14: Familia
A15: Pyrenne Moto 3/24 | B15: 111.98 | C15: Emmanuel
A16: Pyrenne PS5 3/24 | B16: 41.79 | C16: Familia
A17: Arriendo Piso | B17: 827.5 | C17: Familia
A18: Parking | B18: 76.4 | C18: Familia
A19: Trastero | B19: 33.6 | C19: Familia
A20: Ahorro niños | B20: 60 | C20: Familia
A21: Ahorro jubilación | B21: 60 | C21: Familia
A22: Cantina APACEF | B22: 170 | C22: Familia
... A41: Gym | B41: 62.7 | C41: Familia
A47: TOTAL GASTOS | B47: =SUM(B11:B46) -> 3453.63
A49: RESUMEN DEL MES
A50: Total ingresos | B50: =B7 -> 0
A51: Total gastos | B51: =B47 -> 3453.63
A52: AHORRO DEL MES | B52: =B50-B51 -> -3453.63

Sheet Junio 2023
A1: Control Financiero — Junio 2023
A3: INGRESOS DEL MES
A4: Concepto | B4: Importe (€) | C4: Quién | D4: Notas
A5: Nómina Emmanuel | C5: Emmanuel | D5: ← Escribe aquí el día 1
A6: Nómina esposa | C6: Esposa | D6: ← Escribe aquí el día 1
A7: TOTAL INGRESOS | B7: =SUM(B5:B6) -> 0
A9: GASTOS DEL MES
A10: Concepto | B10: Importe (€) | C10: Quién | D10: Notas
A11: Credit Andorra 13/24 | B11: 223.65 | C11: Familia
A12: Pyrennes HP 11/20 | B12: 78.18 | C12: Emmanuel
A13: Pyrennes iPhone 6/24 | B13: 62.43 | C13: Emmanuel
A14: Pyrenne Dacia 23/60 | B14: 230.25 | C14: Familia
A15: Pyrenne Moto 4/24 | B15: 111.98 | C15: Emmanuel
A16: Pyrenne PS5 4/24 | B16: 41.79 | C16: Familia
A17: Arriendo Piso | B17: 827.5 | C17: Familia
A18: Parking | B18: 76.4 | C18: Familia
A19: Trastero | B19: 33.6 | C19: Familia
A20: Ahorro niños | B20: 60 | C20: Familia
A21: Ahorro Elisel | B21: 30 | C21: Esposa
A22: Ahorro Emmanuel | B22: 30 | C22: Emmanuel
... A42: Hospital comida Eli | B42: 18.2 | C42: Esposa
A48: TOTAL GASTOS | B48: =SUM(B11:B47) -> 3079.04
A50: RESUMEN DEL MES
A51: Total ingresos | B51: =B7 -> 0
A52: Total gastos | B52: =B48 -> 3079.04
A53: AHORRO DEL MES | B53: =B51-B52 -> -3079.04

Sheet Julio 2023
A1: Control Financiero — Julio 2023
A3: INGRESOS DEL MES
A4: Concepto | B4: Importe (€) | C4: Quién | D4: Notas
A5: Nómina Emmanuel | C5: Emmanuel | D5: ← Escribe aquí el día 1
A6: Nómina esposa | C6: Esposa | D6: ← Escribe aquí el día 1
A7: TOTAL INGRESOS | B7: =SUM(B5:B6) -> 0
A9: GASTOS DEL MES
A10: Concepto | B10: Importe (€) | C10: Quién | D10: Notas
A11: Pyrennes TV 1/6 | B11: 56.25 | C11: Familia
A12: Credit Andorra 14/24 | B12: 227.82 | C12: Familia
A13: Pyrennes HP 12/20 | B13: 78.18 | C13: Emmanuel
A14: Pyrennes iPhone 14 7/24 | B14: 62.43 | C14: Emmanuel
A15: Pyrenne Dacia 24/60 | B15: 230.25 | C15: Familia
A16: Pyrenne Moto 5/24 | B16: 111.98 | C16: Emmanuel
A17: Pyrenne PS5 5/24 | B17: 41.79 | C17: Familia
A18: Gym Eli | B18: 62.7 | C18: Esposa
A19: Arriendo Piso | B19: 827.5 | C19: Familia
A20: Parking coche | B20: 76.4 | C20: Familia
A21: Trastero | B21: 33.6 | C21: Familia
A22: Ahorro niños | B22: 60 | C22: Familia
... A40: Credit salud | B40: 89.28 | C40: Familia
A41: Vía-T | B41: 12.78 | C41: Familia | D41: 04/03/23-31/01/24
A42: Remesa COIA julio 2023 | B42: 47.03 | C42: Familia
A48: TOTAL GASTOS | B48: =SUM(B11:B47) -> 3284.64
A50: RESUMEN DEL MES
A51: Total ingresos | B51: =B7 -> 0
A52: Total gastos | B52: =B48 -> 3284.64
A53: AHORRO DEL MES | B53: =B51-B52 -> -3284.64

Sheet Agosto 2023
A1: Control Financiero — Agosto 2023
A3: INGRESOS DEL MES
A4: Concepto | B4: Importe (€) | C4: Quién | D4: Notas
A5: Nómina Emmanuel | C5: Emmanuel | D5: ← Escribe aquí el día 1
A6: Nómina esposa | C6: Esposa | D6: ← Escribe aquí el día 1
A7: TOTAL INGRESOS | B7: =SUM(B5:B6) -> 0
A9: GASTOS DEL MES
A10: Concepto | B10: Importe (€) | C10: Quién | D10: Notas
A11: Credit Andorra 15/24 | B11: 227.82 | C11: Familia
A12: Pyrenne JBL Lenovo 1/3 | B12: 165.85 | C12: Familia
A13: Pyrenne TV 2/6 | B13: 44.35 | C13: Familia
A14: Pyrenne HP 13/20 | B14: 78.18 | C14: Emmanuel
A15: Pyrenne iPhone 14 8/24 | B15: 62.43 | C15: Emmanuel
A16: Pyrenne Dacia 25/60 | B16: 230.25 | C16: Familia
A17: Pyrenne Moto 6/24 | B17: 111.98 | C17: Emmanuel
A18: Pyrenne PS5 6/24 | B18: 41.79 | C18: Familia
A19: Gym Eli | B19: 62.7 | C19: Esposa
A20: Arriendo Piso | B20: 827.5 | C20: Familia
A21: Parking coche | B21: 76.4 | C21: Familia
A22: Trastero | B22: 33.6 | C22: Familia
... A42: Credit baja 2 | B42: 20.01 | C42: Familia
A48: TOTAL GASTOS | B48: =SUM(B11:B47) -> 4071.14
A50: RESUMEN DEL MES
A51: Total ingresos | B51: =B7 -> 0
A52: Total gastos | B52: =B48 -> 4071.14
A53: AHORRO DEL MES | B53: =B51-B52 -> -4071.14

Sheet Septiembre 2023
A1: Control Financiero — Septiembre 2023
A3: INGRESOS DEL MES
A4: Concepto | B4: Importe (€) | C4: Quién | D4: Notas
A5: Nómina Emmanuel | C5: Emmanuel | D5: ← Escribe aquí el día 1
A6: Nómina esposa | C6: Esposa | D6: ← Escribe aquí el día 1
A7: TOTAL INGRESOS | B7: =SUM(B5:B6) -> 0
A9: GASTOS DEL MES
A10: Concepto | B10: Importe (€) | C10: Quién | D10: Notas
A11: Peaje viaje Suiza | B11: 157 | C11: Familia
A12: Pyrenne JBL Lenovo 2/3 | B12: 156.44 | C12: Familia
A13: Pyrenne GoPro 1/6 | B13: 68.58 | C13: Familia
A14: Credit Andorra 16/24 | B14: 227.82 | C14: Familia
A15: Pyrenne TV 3/6 | B15: 44.35 | C15: Familia
A16: Pyrenne HP 14/20 | B16: 78.18 | C16: Emmanuel
A17: Pyrenne iPhone 14 9/24 | B17: 62.43 | C17: Emmanuel
A18: Pyrenne Dacia 26/60 | B18: 230.25 | C18: Familia
A19: Moto 7/24 | B19: 111.98 | C19: Emmanuel
A20: Pyrenne PS5 7/24 | B20: 41.79 | C20: Familia
A21: Gym Elisel | B21: 62.7 | C21: Esposa
A22: Arriendo Piso | B22: 827.5 | C22: Familia
... A44: My Pyri Elisel | B44: 60.43 | C44: Esposa
A50: TOTAL GASTOS | B50: =SUM(B11:B49) -> 3691.67
A52: RESUMEN DEL MES
A53: Total ingresos | B53: =B7 -> 0
A54: Total gastos | B54: =B50 -> 3691.67
A55: AHORRO DEL MES | B55: =B53-B54 -> -3691.67

Sheet Octubre 2023
A1: Control Financiero — Octubre 2023
A3: INGRESOS DEL MES
A4: Concepto | B4: Importe (€) | C4: Quién | D4: Notas
A5: Nómina Emmanuel | C5: Emmanuel | D5: ← Escribe aquí el día 1
A6: Nómina esposa | C6: Esposa | D6: ← Escribe aquí el día 1
A7: TOTAL INGRESOS | B7: =SUM(B5:B6) -> 0
A9: GASTOS DEL MES
A10: Concepto | B10: Importe (€) | C10: Quién | D10: Notas
A11: Rodisnet | B11: 14.14 | C11: Familia
A12: Microsoft | B12: 7 | C12: Emmanuel
A13: Pyrenne JBL Lenovo 3/3 | B13: 756.43 | C13: Familia
A14: My Pyri Emmanuel | B14: 421.41 | C14: Emmanuel
A15: Cuota socio anual APACEF | B15: 30.8 | C15: Familia
A16: Viamoda 3/3 | B16: 40.55 | C16: Familia
A17: Pyrenne GoPro 2/6 | B17: 54.12 | C17: Familia
A18: Credit Andorra 17/24 | B18: 227.82 | C18: Familia
A19: Pyrenne TV 4/6 | B19: 44.35 | C19: Familia
A20: Pyrenne HP 15/20 | B20: 78.18 | C20: Emmanuel
A21: Pyrenne iPhone 14 10/24 | B21: 62.43 | C21: Emmanuel
A22: Dacia 27/60 | B22: 230.25 | C22: Familia
... A51: Comida hospital | B51: 4.13 | C51: Familia
A57: TOTAL GASTOS | B57: =SUM(B11:B56) -> 4493.53
A59: RESUMEN DEL MES
A60: Total ingresos | B60: =B7 -> 0
A61: Total gastos | B61: =B57 -> 4493.53
A62: AHORRO DEL MES | B62: =B60-B61 -> -4493.53

Sheet Noviembre 2023
A1: Control Financiero — Noviembre 2023
A3: INGRESOS DEL MES
A4: Concepto | B4: Importe (€) | C4: Quién | D4: Notas
A5: Nómina Emmanuel | C5: Emmanuel | D5: ← Escribe aquí el día 1
A6: Nómina esposa | C6: Esposa | D6: ← Escribe aquí el día 1
A7: TOTAL INGRESOS | B7: =SUM(B5:B6) -> 0
A9: GASTOS DEL MES
A10: Concepto | B10: Importe (€) | C10: Quién | D10: Notas
A11: Microsoft 11 noviembre | B11: 7 | C11: Emmanuel
A12: Pyrenne GoPro 3/6 | B12: 54.12 | C12: Familia
A13: Pyrenne TV 5/6 | B13: 44.35 | C13: Familia
A14: Pyrenne HP 16/20 | B14: 78.18 | C14: Emmanuel
A15: Pyrenne iPhone 14 11/24 | B15: 62.13 | C15: Emmanuel
A16: Pyrenne Dacia 28/60 | B16: 230.25 | C16: Familia
A17: Moto 9/24 | B17: 111.98 | C17: Emmanuel
A18: Pyrenne PS5 9/24 | B18: 41.79 | C18: Familia
A19: Credit Andorra 18/24 | B19: 227.82 | C19: Familia
A20: Gym | B20: 62.7 | C20: Familia
A21: Arriendo Piso | B21: 827.5 | C21: Familia
A22: Parking | B22: 76.4 | C22: Familia
... A45: Consulta Nutrición | B45: 50 | C45: Familia
A46: Disney | B46: 1.99 | C46: Familia | D46: 9-11 cancelado
A47: Viamoda 1/3 | B47: 27.28 | C47: Familia
A53: TOTAL GASTOS | B53: =SUM(B11:B52) -> 3687.35
A55: RESUMEN DEL MES
A56: Total ingresos | B56: =B7 -> 0
A57: Total gastos | B57: =B53 -> 3687.35
A58: AHORRO DEL MES | B58: =B56-B57 -> -3687.35

Sheet Diciembre 2023
A1: Control Financiero — Diciembre 2023
A3: INGRESOS DEL MES
A4: Concepto | B4: Importe (€) | C4: Quién | D4: Notas
A5: Nómina Emmanuel | C5: Emmanuel | D5: ← Escribe aquí el día 1
A6: Nómina esposa | C6: Esposa | D6: ← Escribe aquí el día 1
A7: TOTAL INGRESOS | B7: =SUM(B5:B6) -> 0
A9: GASTOS DEL MES
A10: Concepto | B10: Importe (€) | C10: Quién | D10: Notas
A11: Microsoft último mes mensual | B11: 7 | C11: Emmanuel
A12: Póliza Piso devuelto | B12: 47.75 | C12: Familia
A13: Pyrenne GoPro 4/6 | B13: 54.12 | C13: Familia
A14: Pyrenne TV 6/6 | B14: 44.35 | C14: Familia
A15: Pyrenne HP 17/20 | B15: 78.18 | C15: Emmanuel
A16: Pyrenne iPhone 14 12/24 | B16: 62.43 | C16: Emmanuel
A17: Pyrenne Dacia 29/60 | B17: 230.25 | C17: Familia
A18: Moto 10/24 | B18: 111.98 | C18: Emmanuel
A19: Pyrenne PS5 10/24 | B19: 41.79 | C19: Familia
A20: Credit Andorra 19/24 | B20: 227.82 | C20: Familia
A21: Gym | B21: 62.7 | C21: Familia
A22: Arriendo Piso | B22: 827.5 | C22: Familia
... A47: Credit baja Elisel | B47: 29.57 | C47: Esposa
A53: TOTAL GASTOS | B53: =SUM(B11:B52) -> 3972.16
A55: RESUMEN DEL MES
A56: Total ingresos | B56: =B7 -> 0
A57: Total gastos | B57: =B53 -> 3972.16
A58: AHORRO DEL MES | B58: =B56-B57 -> -3972.16

Sheet Enero 2024
A1: Control Financiero — Enero 2024
A3: INGRESOS DEL MES
A4: Concepto | B4: Importe (€) | C4: Quién | D4: Notas
A5: Nómina Emmanuel | C5: Emmanuel | D5: ← Escribe aquí el día 1
A6: Nómina esposa | C6: Esposa | D6: ← Escribe aquí el día 1
A7: TOTAL INGRESOS | B7: =SUM(B5:B6) -> 0
A9: GASTOS DEL MES
A10: Concepto | B10: Importe (€) | C10: Quién | D10: Notas
A11: Microsoft mensual | B11: 7 | C11: Emmanuel | D11: 11 enero
A12: Póliza moto anual | B12: 95.54 | C12: Emmanuel
A13: Neumático 2/6 | B13: 115.29 | C13: Familia
A14: Colegio Enfermería semestral | B14: 47.03 | C14: Esposa | D14: 11 enero
A15: GoPro 3/6 | B15: 54.12 | C15: Familia
A16: HP 18/20 | B16: 78.18 | C16: Emmanuel
A17: iPhone 14 13/24 | B17: 62.43 | C17: Emmanuel
A18: Dacia 30/60 | B18: 230.25 | C18: Familia
A19: Moto 11/24 | B19: 111.98 | C19: Emmanuel
A20: PS5 11/24 | B20: 41.79 | C20: Familia
A21: Credit Andorra 20/24 | B21: 227.82 | C21: Familia
A22: Gym | B22: 62.7 | C22: Familia
A23: Piso | B23: 827.5 | C23: Familia
A24: Parking | B24: 76.4 | C24: Familia
A25: Trastero | B25: 33.6 | C25: Familia
A26: Credit salud complementario | B26: 64.24 | C26: Familia
... A47: Aval Pyrennes anual | B47: 16.43 | C47: Familia
A53: TOTAL GASTOS | B53: =SUM(B11:B52) -> 4463.68
A55: RESUMEN DEL MES
A56: Total ingresos | B56: =B7 -> 0
A57: Total gastos | B57: =B53 -> 4463.68
A58: AHORRO DEL MES | B58: =B56-B57 -> -4463.68

Sheet Febrero 2024
A1: Control Financiero — Febrero 2024
A3: INGRESOS DEL MES
A4: Concepto | B4: Importe (€) | C4: Quién | D4: Notas
A5: Nómina Emmanuel | C5: Emmanuel | D5: ← Escribe aquí el día 1
A6: Nómina esposa | C6: Esposa | D6: ← Escribe aquí el día 1
A7: TOTAL INGRESOS | B7: =SUM(B5:B6) -> 0
A9: GASTOS DEL MES
A10: Concepto | B10: Importe (€) | C10: Quién | D10: Notas
A11: HP Pyrennes 19/20 | B11: 78.18 | C11: Emmanuel
A12: Rodisnet | B12: 19.09 | C12: Familia
A13: Pyrennes Gopro 6/6 | B13: 154.14 | C13: Familia
A14: Neumático 3/6 | B14: 115.29 | C14: Familia
A15: Viaje suegra 2/3 | B15: 288.04 | C15: Familia
A16: iPhone 14/24 | B16: 62.43 | C16: Emmanuel
A17: Dacia 31/60 | B17: 230.25 | C17: Familia
A18: Moto 12/24 | B18: 111.98 | C18: Emmanuel
A19: PS5 12/24 | B19: 41.79 | C19: Familia
A20: Credit Andorra 21/24 | B20: 227.82 | C20: Familia
A21: Piso | B21: 865.04 | C21: Familia
A22: Trastero | B22: 35.11 | C22: Familia
... A46: Telecom Andorra | B46: 79 | C46: Familia
A52: TOTAL GASTOS | B52: =SUM(B11:B51) -> 4785.5
A54: RESUMEN DEL MES
A55: Total ingresos | B55: =B7 -> 0
A56: Total gastos | B56: =B52 -> 4785.5
A57: AHORRO DEL MES | B57: =B55-B56 -> -4785.5

Sheet Marzo 2024
A1: Control Financiero — Marzo 2024
A3: INGRESOS DEL MES
A4: Concepto | B4: Importe (€) | C4: Quién | D4: Notas
A5: Nómina Emmanuel | C5: Emmanuel | D5: ← Escribe aquí el día 1
A6: Nómina esposa | C6: Esposa | D6: ← Escribe aquí el día 1
A7: TOTAL INGRESOS | B7: =SUM(B5:B6) -> 0
A9: GASTOS DEL MES
A10: Concepto | B10: Importe (€) | C10: Quién | D10: Notas
A11: Congelador 2/6 | B11: 64 | C11: Familia
A12: HP Pyrennes 20/20 | B12: 78.23 | C12: Emmanuel
A13: Viamoda 3/3 | B13: 58.18 | C13: Familia
A14: Neumático 4/6 | B14: 115.24 | C14: Familia
A15: Viaje suegra 3/3 | B15: 288.03 | C15: Familia
A16: Cantina actividad | B16: 223.5 | C16: Familia
A17: iPhone 14 15/24 | B17: 62.43 | C17: Emmanuel
A18: Dacia 32/60 | B18: 230.25 | C18: Familia
A19: Moto 13/24 | B19: 111.98 | C19: Emmanuel
A20: PS5 13/24 | B20: 41.79 | C20: Familia
A21: Credit Andorra 22/24 | B21: 227.82 | C21: Familia
A22: Gym | B22: 67.9 | C22: Familia
... A42: My Piri Elisel | B42: 364.92 | C42: Esposa
A48: TOTAL GASTOS | B48: =SUM(B11:B47) -> 4997.31
A50: RESUMEN DEL MES
A51: Total ingresos | B51: =B7 -> 0
A52: Total gastos | B52: =B48 -> 4997.31
A53: AHORRO DEL MES | B53: =B51-B52 -> -4997.31

Sheet Abril 2024
A1: Control Financiero — Abril 2024
A3: INGRESOS DEL MES
A4: Concepto | B4: Importe (€) | C4: Quién | D4: Notas
A5: Nómina Emmanuel | C5: Emmanuel | D5: ← Escribe aquí el día 1
A6: Nómina esposa | C6: Esposa | D6: ← Escribe aquí el día 1
A7: TOTAL INGRESOS | B7: =SUM(B5:B6) -> 0
A9: GASTOS DEL MES
A10: Concepto | B10: Importe (€) | C10: Quién | D10: Notas
A11: Congelador 3/6 | B11: 64 | C11: Familia
A12: Neumático 5/6 | B12: 115.29 | C12: Familia
A13: Becier 3/6 | B13: 96.47 | C13: Familia
A14: Gym | B14: 67.9 | C14: Familia
A15: Dacia 33/60 | B15: 230.25 | C15: Familia
A16: Moto 14/24 | B16: 111.98 | C16: Emmanuel
A17: PS5 14/24 | B17: 41.79 | C17: Familia
A18: iPhone 16/24 | B18: 62.43 | C18: Emmanuel
A19: Telecom Andorra | B19: 12.05 | C19: Familia
A20: Credit baja Emmanuel | B20: 17.34 | C20: Emmanuel
A21: Credit baja Elisel | B21: 24.52 | C21: Esposa
A22: Credit capital Emmanuel | B22: 15.27 | C22: Emmanuel
... A38: Viamoda | B38: 15.5 | C38: Familia
A44: TOTAL GASTOS | B44: =SUM(B11:B43) -> 3892
A46: RESUMEN DEL MES
A47: Total ingresos | B47: =B7 -> 0
A48: Total gastos | B48: =B44 -> 3892
A49: AHORRO DEL MES | B49: =B47-B48 -> -3892

Sheet Mayo 2024
A1: Control Financiero — Mayo 2024
A3: INGRESOS DEL MES
A4: Concepto | B4: Importe (€) | C4: Quién | D4: Notas
A5: Nómina Emmanuel | C5: Emmanuel | D5: ← Escribe aquí el día 1
A6: Nómina esposa | C6: Esposa | D6: ← Escribe aquí el día 1
A7: TOTAL INGRESOS | B7: =SUM(B5:B6) -> 0
A9: GASTOS DEL MES
A10: Concepto | B10: Importe (€) | C10: Quién | D10: Notas
A11: Congelador 4/6 | B11: 64 | C11: Familia
A12: Neumático | B12: 115.84 | C12: Familia
A13: Credit Andorra 24/24 | B13: 227.82 | C13: Familia
A14: Dacia 34/60 | B14: 230.25 | C14: Familia
A15: Moto 15/24 | B15: 111.98 | C15: Emmanuel
A16: PS5 15/24 | B16: 41.79 | C16: Familia
A17: iPhone 17/24 | B17: 62.43 | C17: Emmanuel
A18: Telecom Andorra | B18: 50 | C18: Familia
A19: Credit baja Emmanuel | B19: 17.05 | C19: Emmanuel
A20: Credit baja Elisel | B20: 29.59 | C20: Esposa
A21: Credit capital Elisel | B21: 18.56 | C21: Esposa
A22: Credit capital Emmanuel | B22: 15.27 | C22: Emmanuel
... A39: Foc i lloc comida | B39: 60.29 | C39: Familia
A45: TOTAL GASTOS | B45: =SUM(B11:B44) -> 4233.26
A47: RESUMEN DEL MES
A48: Total ingresos | B48: =B7 -> 0
A49: Total gastos | B49: =B45 -> 4233.26
A50: AHORRO DEL MES | B50: =B48-B49 -> -4233.26

Sheet Junio 2024
A1: Control Financiero — Junio 2024
A3: INGRESOS DEL MES
A4: Concepto | B4: Importe (€) | C4: Quién | D4: Notas
A5: Nómina Emmanuel | C5: Emmanuel | D5: ← Escribe aquí el día 1
A6: Nómina esposa | C6: Esposa | D6: ← Escribe aquí el día 1
A7: TOTAL INGRESOS | B7: =SUM(B5:B6) -> 0
A9: GASTOS DEL MES
A10: Concepto | B10: Importe (€) | C10: Quién | D10: Notas
A11: Congelador 5/6 | B11: 64 | C11: Familia
A12: Gym | B12: 67.9 | C12: Familia
A13: Dacia 35/60 | B13: 230.25 | C13: Familia | D13: 3 años
A14: Moto 16/24 | B14: 111.98 | C14: Emmanuel
A15: PS5 16/24 | B15: 41.79 | C15: Familia
A16: iPhone 18/24 | B16: 62.43 | C16: Emmanuel
A17: Telecom Andorra | B17: 72.74 | C17: Familia
A18: Credit baja Emmanuel | B18: 17.05 | C18: Emmanuel
A19: Credit baja Elisel | B19: 29.57 | C19: Esposa
A20: Credit capital Elisel | B20: 18.56 | C20: Esposa
A21: Credit capital Emmanuel | B21: 15.27 | C21: Emmanuel
A22: Credit salud complementario | B22: 64.24 | C22: Familia
A23: Piso | B23: 865.04 | C23: Familia
A24: Trastero | B24: 35.11 | C24: Familia
A25: Parking | B25: 101.5 | C25: Familia
... A42: Moto impuesto anual | B42: 19 | C42: Emmanuel
A48: TOTAL GASTOS | B48: =SUM(B11:B47) -> 4000.27
A50: RESUMEN DEL MES
A51: Total ingresos | B51: =B7 -> 0
A52: Total gastos | B52: =B48 -> 4000.27
A53: AHORRO DEL MES | B53: =B51-B52 -> -4000.27

Sheet Julio 2024
A1: Control Financiero — Julio 2024
A3: INGRESOS DEL MES
A4: Concepto | B4: Importe (€) | C4: Quién | D4: Notas
A5: Nómina Emmanuel | C5: Emmanuel | D5: ← Escribe aquí el día 1
A6: Nómina esposa | C6: Esposa | D6: ← Escribe aquí el día 1
A7: TOTAL INGRESOS | B7: =SUM(B5:B6) -> 0
A9: GASTOS DEL MES
A10: Concepto | B10: Importe (€) | C10: Quién | D10: Notas
A11: Congelador 6/6 | B11: 64 | C11: Familia
A12: Gym | B12: 67.9 | C12: Familia
A13: Dacia 36/60 | B13: 230.25 | C13: Familia | D13: 3 años
A14: Moto 17/24 | B14: 111.98 | C14: Emmanuel
A15: PS5 17/24 | B15: 41.79 | C15: Familia
A16: iPhone 19/24 | B16: 62.43 | C16: Emmanuel
A17: Telecom Andorra | B17: 84.71 | C17: Familia
A18: Credit baja Emmanuel | B18: 17.05 | C18: Emmanuel
A19: Credit baja Elisel | B19: 29.57 | C19: Esposa
A20: Credit capital Elisel | B20: 18.56 | C20: Esposa
A21: Credit capital Emmanuel | B21: 15.27 | C21: Emmanuel
A22: Credit salud complementario | B22: 64.24 | C22: Familia
A23: Piso | B23: 865.04 | C23: Familia
A24: Trastero | B24: 35.11 | C24: Familia
A25: Parking | B25: 101.5 | C25: Familia
... A40: Aval tarjeta Pyrennes anual | B40: 16.43 | C40: Familia
A46: TOTAL GASTOS | B46: =SUM(B11:B45) -> 4269.7
A48: RESUMEN DEL MES
A49: Total ingresos | B49: =B7 -> 0
A50: Total gastos | B50: =B46 -> 4269.7
A51: AHORRO DEL MES | B51: =B49-B50 -> -4269.7

Sheet Agosto 2024
A1: Control Financiero — Agosto 2024
A3: INGRESOS DEL MES
A4: Concepto | B4: Importe (€) | C4: Quién | D4: Notas
A5: Nómina Emmanuel | C5: Emmanuel | D5: ← Escribe aquí el día 1
A6: Nómina esposa | C6: Esposa | D6: ← Escribe aquí el día 1
A7: TOTAL INGRESOS | B7: =SUM(B5:B6) -> 0
A9: GASTOS DEL MES
A10: Concepto | B10: Importe (€) | C10: Quién | D10: Notas
A11: Gym | B11: 67.9 | C11: Familia
A12: Dacia 37/60 | B12: 230.25 | C12: Familia
A13: Moto 18/24 | B13: 111.98 | C13: Emmanuel
A14: PS5 18/24 | B14: 41.79 | C14: Familia
A15: iPhone 20/24 | B15: 62.43 | C15: Emmanuel
A16: Telecom Andorra | B16: 73 | C16: Familia
A17: Credit baja Emmanuel | B17: 17.05 | C17: Emmanuel
A18: Credit baja Elisel | B18: 29.57 | C18: Esposa
A19: Credit capital Elisel | B19: 18.56 | C19: Esposa
A20: Credit capital Emmanuel | B20: 15.27 | C20: Emmanuel
A21: Credit salud complementario | B21: 64.24 | C21: Familia
A22: Piso | B22: 865.04 | C22: Familia
... A37: Multiseguro | B37: 113 | C37: Familia
A43: TOTAL GASTOS | B43: =SUM(B11:B42) -> 3734.13
A45: RESUMEN DEL MES
A46: Total ingresos | B46: =B7 -> 0
A47: Total gastos | B47: =B43 -> 3734.13
A48: AHORRO DEL MES | B48: =B46-B47 -> -3734.13

Sheet Septiembre 2024
A1: Control Financiero — Septiembre 2024
A3: INGRESOS DEL MES
A4: Concepto | B4: Importe (€) | C4: Quién | D4: Notas
A5: Nómina Emmanuel | C5: Emmanuel | D5: ← Escribe aquí el día 1
A6: Nómina esposa | C6: Esposa | D6: ← Escribe aquí el día 1
A7: TOTAL INGRESOS | B7: =SUM(B5:B6) -> 0
A9: GASTOS DEL MES
A10: Concepto | B10: Importe (€) | C10: Quién | D10: Notas
A11: Gym | B11: 67.9 | C11: Familia | D11: 27 fiesta Emilia
A12: Cumpleaño Emiliano | B12: 250 | C12: Familia
A13: APACEF | B13: 185 | C13: Familia
A14: Boleto viaje 3/3 | B14: 373.34 | C14: Familia
A15: Dacia 38/60 | B15: 230.25 | C15: Familia
A16: Moto 19/24 | B16: 111.98 | C16: Emmanuel
A17: PS5 19/24 | B17: 41.79 | C17: Familia
A18: iPhone 21/24 | B18: 62.43 | C18: Emmanuel
A19: Alexa 3/3 | B19: 50 | C19: Familia
A20: TV 2/3 | B20: 107.64 | C20: Familia
A21: Nevera 4/6 | B21: 71.37 | C21: Familia
A22: SAAS 3/12 | B22: 208 | C22: Familia
A23: Telecom Andorra | B23: 86.53 | C23: Familia
... A40: Rodisnet | B40: 37.66 | C40: Familia
A46: TOTAL GASTOS | B46: =SUM(B11:B45) -> 4380.06
A48: RESUMEN DEL MES
A49: Total ingresos | B49: =B7 -> 0
A50: Total gastos | B50: =B46 -> 4380.06
A51: AHORRO DEL MES | B51: =B49-B50 -> -4380.06

Sheet Octubre 2024
A1: Control Financiero — Octubre 2024
A3: INGRESOS DEL MES
A4: Concepto | B4: Importe (€) | C4: Quién | D4: Notas
A5: Nómina Emmanuel | C5: Emmanuel | D5: ← Escribe aquí el día 1
A6: Nómina esposa | C6: Esposa | D6: ← Escribe aquí el día 1
A7: TOTAL INGRESOS | B7: =SUM(B5:B6) -> 0
A9: GASTOS DEL MES
A10: Concepto | B10: Importe (€) | C10: Quién | D10: Notas
A11: Cuota APACEF anual | B11: 30.8 | C11: Familia | D11: ITV Dacia
A12: APACEF | B12: 250.9 | C12: Familia
A13: Gym | B13: 67.9 | C13: Familia
A14: Dacia 39/60 | B14: 230.25 | C14: Familia
A15: Moto 20/24 | B15: 111.98 | C15: Emmanuel
A16: PS5 20/24 | B16: 41.79 | C16: Familia
A17: iPhone 21/24 | B17: 62.43 | C17: Emmanuel
A18: TV 3/3 | B18: 107.65 | C18: Familia
A19: Nevera 5/6 | B19: 71.37 | C19: Familia
A20: SAAS 4/12 | B20: 208 | C20: Familia
A21: Telecom Andorra | B21: 73 | C21: Familia
A22: FEDA | B22: 98.18 | C22: Familia
A23: Tarjeta crédito Morabanc | B23: 400 | C23: Familia
... A37: Fundació Meritxell | B37: 42 | C37: Familia
A43: TOTAL GASTOS | B43: =SUM(B11:B42) -> 4262.95
A45: RESUMEN DEL MES
A46: Total ingresos | B46: =B7 -> 0
A47: Total gastos | B47: =B43 -> 4262.95
A48: AHORRO DEL MES | B48: =B46-B47 -> -4262.95

Sheet Noviembre 2024
A1: Control Financiero — Noviembre 2024
A3: INGRESOS DEL MES
A4: Concepto | B4: Importe (€) | C4: Quién | D4: Notas
A5: Nómina Emmanuel | C5: Emmanuel | D5: ← Escribe aquí el día 1
A6: Nómina esposa | C6: Esposa | D6: ← Escribe aquí el día 1
A7: TOTAL INGRESOS | B7: =SUM(B5:B6) -> 0
A9: GASTOS DEL MES
A10: Concepto | B10: Importe (€) | C10: Quién | D10: Notas
A11: Pyrennes iPhone 14 23/24 | B11: 62.56 | C11: Emmanuel
A12: Andorra 2000 Elisel | B12: 150 | C12: Esposa
A13: APACEF cantina | B13: 185 | C13: Familia
A14: Gym | B14: 67.9 | C14: Familia
A15: Dacia 40/60 | B15: 230.25 | C15: Familia
A16: Moto 21/24 | B16: 111.98 | C16: Emmanuel
A17: PS5 21/24 | B17: 41.79 | C17: Familia
A18: APACEF actividad | B18: 65 | C18: Familia
A19: Nevera 6/6 | B19: 71.37 | C19: Familia
A20: SAAS 5/12 | B20: 208 | C20: Familia
A21: Telecom Andorra | B21: 75 | C21: Familia
A22: FEDA | B22: 115.92 | C22: Familia
... A26: Parking | B26: 101.5 | C26: Familia
A27: Microsoft | B27: 7 | C27: Emmanuel | D27: 11 noviembre
A28: Credit baja Elisel | B28: 29.57 | C28: Esposa
A29: Credit baja Emmanuel | B29: 17.05 | C29: Emmanuel
A30: Libro inglés Emiliano | B30: 30 | C30: Familia
A31: Credit complementario salud | B31: 64.24 | C31: Familia
A32: Andorra 2000 Emmanuel | B32: 99 | C32: Emmanuel
A33: Netflix | B33: 8 | C33: Familia
A34: Artal | B34: 88.12 | C34: Familia
A35: Rodinet | B35: 68 | C35: Familia
A36: Comedor SAAS | B36: 50 | C36: Familia
A37: Universidad | B37: 400 | C37: Emmanuel
A43: TOTAL GASTOS | B43: =SUM(B11:B42) -> 4025.25
A45: RESUMEN DEL MES
A46: Total ingresos | B46: =B7 -> 0
A47: Total gastos | B47: =B43 -> 4025.25
A48: AHORRO DEL MES | B48: =B46-B47 -> -4025.25

Sheet Diciembre 2024
A1: Control Financiero — Diciembre 2024
A3: INGRESOS DEL MES
A4: Concepto | B4: Importe (€) | C4: Quién | D4: Notas
A5: Nómina Emmanuel | C5: Emmanuel | D5: ← Escribe aquí el día 1
A6: Nómina esposa | C6: Esposa | D6: ← Escribe aquí el día 1
A7: TOTAL INGRESOS | B7: =SUM(B5:B6) -> 0
A9: GASTOS DEL MES
A10: Concepto | B10: Importe (€) | C10: Quién | D10: Notas
A11: Pyrennes iPhone 14 24/24 | B11: 62.56 | C11: Emmanuel
A12: Disney anual | B12: 99.9 | C12: Familia | D12: 23 diciembre
A13: APACEF cantina | B13: 185 | C13: Familia
A14: Gym | B14: 67.9 | C14: Familia
A15: Dacia 41/60 | B15: 230 | C15: Familia
A16: Moto 22/24 | B16: 111.98 | C16: Emmanuel
A17: PS5 22/24 | B17: 41.79 | C17: Familia
A18: SAAS 6/12 | B18: 208 | C18: Familia
A19: Telecom Andorra | B19: 75.54 | C19: Familia
A20: FEDA | B20: 140.92 | C20: Familia
A21: Tarjeta crédito Morabanc | B21: 280.45 | C21: Familia
A22: Piso | B22: 865 | C22: Familia
A23: Trastero | B23: 35 | C23: Familia
A24: Parking | B24: 101.5 | C24: Familia
... A29: Andorra 2000 Emmanuel | B29: 146.71 | C29: Emmanuel
A30: Netflix | B30: 13 | C30: Familia | D30: 22 diciembre
A31: Microsoft | B31: 7 | C31: Emmanuel | D31: 11 diciembre
A32: Suegra | B32: 100 | C32: Familia
A33: Miriam | B33: 100 | C33: Familia
A34: APACEF actividad | B34: 65 | C34: Familia
A35: Artal | B35: 232.34 | C35: Familia
A41: TOTAL GASTOS | B41: =SUM(B11:B40) -> 3418.72
A43: RESUMEN DEL MES
A44: Total ingresos | B44: =B7 -> 0
A45: Total gastos | B45: =B41 -> 3418.72
A46: AHORRO DEL MES | B46: =B44-B45 -> -3418.72

Sheet Enero 2025
A1: Control Financiero — Enero 2025
A3: INGRESOS DEL MES
A4: Concepto | B4: Importe (€) | C4: Quién | D4: Notas
A5: Nómina Emmanuel | C5: Emmanuel | D5: ← Escribe aquí el día 1
A6: Nómina esposa | C6: Esposa | D6: ← Escribe aquí el día 1
A7: TOTAL INGRESOS | B7: =SUM(B5:B6) -> 0
A9: GASTOS DEL MES
A10: Concepto | B10: Importe (€) | C10: Quién | D10: Notas
A11: Alquiler esquí temporada | B11: 231.44 | C11: Familia
A12: Pyrennes PS5 23/24 | B12: 41.67 | C12: Familia
A13: Pyrennes Moto 23/24 | B13: 171.94 | C13: Familia
A14: APACEF | B14: 250 | C14: Familia
A15: Gym | B15: 67.9 | C15: Familia
A16: Dacia 42/60 | B16: 230 | C16: Familia
A17: SAAS 7/12 | B17: 208 | C17: Familia
A18: Piso | B18: 865 | C18: Familia
A19: Trastero | B19: 35 | C19: Familia
A20: Parking Caldea | B20: 101.5 | C20: Familia
A21: FEDA | B21: 200 | C21: Familia
A22: Telecom Andorra | B22: 89 | C22: Familia
... A28: Andorra 2000 Emmanuel | B28: 143 | C28: Emmanuel
A29: Microsoft anual | B29: 69 | C29: Emmanuel | D29: 11 enero
A30: Rodinet | B30: 83 | C30: Familia
A31: Moto póliza | B31: 98 | C31: Emmanuel
A32: Colegio Enfermería | B32: 49.19 | C32: Esposa
A33: Parking Caldea 2 | B33: 153.25 | C33: Familia
A34: Comedor SAAS | B34: 40 | C34: Familia
A35: Póliza piso | B35: 78 | C35: Familia
A41: TOTAL GASTOS | B41: =SUM(B11:B40) -> 4056.89
A43: RESUMEN DEL MES
A44: Total ingresos | B44: =B7 -> 0
A45: Total gastos | B45: =B41 -> 4056.89
A46: AHORRO DEL MES | B46: =B44-B45 -> -4056.89

Sheet Febrero 2025
A1: Control Financiero — Febrero 2025
A3: INGRESOS DEL MES
A4: Concepto | B4: Importe (€) | C4: Quién | D4: Notas
A5: Nómina Emmanuel | C5: Emmanuel | D5: ← Escribe aquí el día 1
A6: Nómina esposa | C6: Esposa | D6: ← Escribe aquí el día 1
A7: TOTAL INGRESOS | B7: =SUM(B5:B6) -> 0
A9: GASTOS DEL MES
A10: Concepto | B10: Importe (€) | C10: Quién | D10: Notas
A11: Moto Pyrennes 24/24 | B11: 111.94 | C11: Emmanuel
A12: PS5 Pyrennes 24/24 | B12: 41.79 | C12: Familia
A13: APACEF | B13: 250 | C13: Familia
A14: Vía-T | B14: 23.66 | C14: Familia
A15: Dacia 43/60 liquidado | B15: 230 | C15: Familia
A16: SAAS 8/12 | B16: 208 | C16: Familia
A17: Piso | B17: 887.23 | C17: Familia
A18: Trastero | B18: 35.98 | C18: Familia
A19: Comida hospital | B19: 49.64 | C19: Familia
A20: FEDA | B20: 203.6 | C20: Familia
A21: Telecom Andorra | B21: 120.21 | C21: Familia
A22: Credit baja Elisel | B22: 29.99 | C22: Esposa
... A33: Rodisnet | B33: 15.56 | C33: Familia
A39: TOTAL GASTOS | B39: =SUM(B11:B38) -> 3889.19
A41: RESUMEN DEL MES
A42: Total ingresos | B42: =B7 -> 0
A43: Total gastos | B43: =B39 -> 3889.19
A44: AHORRO DEL MES | B44: =B42-B43 -> -3889.19

Sheet Marzo 2025
A1: Control Financiero — Marzo 2025
A3: INGRESOS DEL MES
A4: Concepto | B4: Importe (€) | C4: Quién | D4: Notas
A5: Nómina Emmanuel | C5: Emmanuel | D5: ← Escribe aquí el día 1
A6: Nómina esposa | C6: Esposa | D6: ← Escribe aquí el día 1
A7: TOTAL INGRESOS | B7: =SUM(B5:B6) -> 0
A9: GASTOS DEL MES
A10: Concepto | B10: Importe (€) | C10: Quién | D10: Notas
A11: Universidad Carlemany 1/12 TDC | B11: 266.7 | C11: Emmanuel
A12: SAAS 9/12 | B12: 208 | C12: Familia
A13: Rodisnet anual | B13: 47 | C13: Familia
A14: HP 2/3 | B14: 137.6 | C14: Emmanuel
A15: iPhone 2/12 | B15: 128 | C15: Emmanuel
A16: APACEF | B16: 300.8 | C16: Familia
A17: Dacia 1/60 | B17: 337.17 | C17: Familia
A18: Andorra 2000 Emmanuel | B18: 86.11 | C18: Emmanuel
A19: Piso | B19: 887 | C19: Familia
A20: Trastero | B20: 36 | C20: Familia
A21: Andorra 2000 Elisel | B21: 140 | C21: Esposa
A22: FEDA | B22: 144 | C22: Familia
... A29: Tarjeta crédito | B29: 574 | C29: Familia
A35: TOTAL GASTOS | B35: =SUM(B11:B34) -> 3603.37
A37: RESUMEN DEL MES
A38: Total ingresos | B38: =B7 -> 0
A39: Total gastos | B39: =B35 -> 3603.37
A40: AHORRO DEL MES | B40: =B38-B39 -> -3603.37

Sheet Abril 2025
A1: Control Financiero — Abril 2025
A3: INGRESOS DEL MES
A4: Concepto | B4: Importe (€) | C4: Quién | D4: Notas
A5: Nómina Emmanuel | C5: Emmanuel | D5: ← Escribe aquí el día 1
A6: Nómina esposa | C6: Esposa | D6: ← Escribe aquí el día 1
A7: TOTAL INGRESOS | B7: =SUM(B5:B6) -> 0
A9: GASTOS DEL MES
A10: Concepto | B10: Importe (€) | C10: Quién | D10: Notas
A11: SAAS 10/12 | B11: 208 | C11: Familia
A12: Universidad Carlemany 2/12 TDC | B12: 266.7 | C12: Emmanuel
A13: HP 3/3 | B13: 137.6 | C13: Emmanuel
A14: iPhone 3/12 | B14: 128 | C14: Emmanuel
A15: APACEF | B15: 300 | C15: Familia
A16: Dacia 2/60 | B16: 337.17 | C16: Familia
A17: Piso | B17: 887 | C17: Familia
A18: Trastero | B18: 36 | C18: Familia
A19: Andorra 2000 Emmanuel | B19: 136.47 | C19: Emmanuel
A20: FEDA | B20: 175 | C20: Familia
A21: Telecom Andorra | B21: 106 | C21: Familia
A22: Credit baja Elisel | B22: 29.99 | C22: Esposa
... A28: Andorra 2000 Elisel | B28: 144.98 | C28: Esposa
A29: Parking aeropuerto AENA | B29: 60.8 | C29: Familia | D29: 29 abril
A30: Tarjeta crédito | B30: 8.53 | C30: Familia
A31: Rodisnet | B31: 10 | C31: Familia
A32: Rent coche Malta 23 abril | B32: 194.5 | C32: Familia
A33: Fianza rent coche Malta 28 abril | B33: 150 | C33: Familia
A34: Artal | B34: 50 | C34: Familia
A40: TOTAL GASTOS | B40: =SUM(B11:B39) -> 3665.73
A42: RESUMEN DEL MES
A43: Total ingresos | B43: =B7 -> 0
A44: Total gastos | B44: =B40 -> 3665.73
A45: AHORRO DEL MES | B45: =B43-B44 -> -3665.73

Sheet Mayo 2025
A1: Control Financiero — Mayo 2025
A3: INGRESOS DEL MES
A4: Concepto | B4: Importe (€) | C4: Quién | D4: Notas
A5: Nómina Emmanuel | C5: Emmanuel | D5: ← Escribe aquí el día 1
A6: Nómina esposa | C6: Esposa | D6: ← Escribe aquí el día 1
A7: TOTAL INGRESOS | B7: =SUM(B5:B6) -> 0
A9: GASTOS DEL MES
A10: Concepto | B10: Importe (€) | C10: Quién | D10: Notas
A11: Morabanc 1/24 | B11: 292 | C11: Familia
A12: SAAS 11/12 | B12: 208 | C12: Familia
A13: Universidad 3/12 | B13: 266 | C13: Emmanuel
A14: APACEF | B14: 250 | C14: Familia
A15: Dacia 3/60 | B15: 337.17 | C15: Familia
A16: Piso | B16: 887 | C16: Familia
A17: Tarjeta crédito | B17: 826 | C17: Familia
A18: FEDA | B18: 85 | C18: Familia
A19: Telecom | B19: 100 | C19: Familia
A20: Credit baja Elisel | B20: 30 | C20: Esposa
A21: Credit baja Emmanuel | B21: 17 | C21: Emmanuel
A22: Parking | B22: 85 | C22: Familia
... A28: Artal | B28: 90.68 | C28: Familia
A34: TOTAL GASTOS | B34: =SUM(B11:B33) -> 3820.58
A36: RESUMEN DEL MES
A37: Total ingresos | B37: =B7 -> 0
A38: Total gastos | B38: =B34 -> 3820.58
A39: AHORRO DEL MES | B39: =B37-B38 -> -3820.58

Sheet Junio 2025
A1: Control Financiero — Junio 2025
A3: INGRESOS DEL MES
A4: Concepto | B4: Importe (€) | C4: Quién | D4: Notas
A5: Nómina Emmanuel | C5: Emmanuel | D5: ← Escribe aquí el día 1
A6: Nómina esposa | C6: Esposa | D6: ← Escribe aquí el día 1
A7: TOTAL INGRESOS | B7: =SUM(B5:B6) -> 0
A9: GASTOS DEL MES
A10: Concepto | B10: Importe (€) | C10: Quién | D10: Notas
A11: Morabanc 2/24 | B11: 292 | C11: Familia
A12: SAAS 12/12 | B12: 208 | C12: Familia
A13: Universidad 4/12 TDC | B13: 266 | C13: Emmanuel
A14: PIAM | B14: 111 | C14: Familia
A15: APACEF | B15: 250 | C15: Familia
A16: Dacia 4/60 | B16: 337.17 | C16: Familia
A17: Piso | B17: 887 | C17: Familia
A18: FEDA | B18: 102 | C18: Familia
A19: Telecom | B19: 100 | C19: Familia
A20: Credit baja Elisel | B20: 30 | C20: Esposa
A21: Credit baja Emmanuel | B21: 17 | C21: Emmanuel
A22: Parking | B22: 85 | C22: Familia
... A31: Comedor Elisel | B31: 39.71 | C31: Esposa
A37: TOTAL GASTOS | B37: =SUM(B11:B36) -> 3544.09
A39: RESUMEN DEL MES
A40: Total ingresos | B40: =B7 -> 0
A41: Total gastos | B41: =B37 -> 3544.09
A42: AHORRO DEL MES | B42: =B40-B41 -> -3544.09

Sheet Julio 2025
A1: Control Financiero — Julio 2025
A3: INGRESOS DEL MES
A4: Concepto | B4: Importe (€) | C4: Quién | D4: Notas
A5: Nómina Emmanuel | C5: Emmanuel | D5: ← Escribe aquí el día 1
A6: Nómina esposa | C6: Esposa | D6: ← Escribe aquí el día 1
A7: TOTAL INGRESOS | B7: =SUM(B5:B6) -> 0
A9: GASTOS DEL MES
A10: Concepto | B10: Importe (€) | C10: Quién | D10: Notas
A11: Rodisnet | B11: 47 | C11: Familia
A12: Colegio Enfermería | B12: 49.29 | C12: Esposa
A13: Morabanc 3/24 | B13: 292 | C13: Familia | D13: préstamo
A14: Universidad 5/12 TDC | B14: 266 | C14: Emmanuel
A15: Tarjeta crédito | B15: 1000 | C15: Familia
A16: Dacia 5/60 | B16: 337 | C16: Familia
A17: Piso | B17: 887 | C17: Familia
A18: Trastero | B18: 127 | C18: Familia
A19: FEDA | B19: 137 | C19: Familia
A20: Telecom Andorra | B20: 100 | C20: Familia
A21: Credit baja Elisel | B21: 30 | C21: Esposa
A22: Credit baja Emmanuel | B22: 17 | C22: Emmanuel
A23: Parking | B23: 85 | C23: Familia
A24: Becier 4/6 | B24: 116 | C24: Familia
A25: Netflix TDC | B25: 13 | C25: Familia
... A28: Comida SAAS | B28: 59.57 | C28: Familia
A34: TOTAL GASTOS | B34: =SUM(B11:B33) -> 3914.86
A36: RESUMEN DEL MES
A37: Total ingresos | B37: =B7 -> 0
A38: Total gastos | B38: =B34 -> 3914.86
A39: AHORRO DEL MES | B39: =B37-B38 -> -3914.86

Sheet Agosto 2025
A1: Control Financiero — Agosto 2025
A3: INGRESOS DEL MES
A4: Concepto | B4: Importe (€) | C4: Quién | D4: Notas
A5: Nómina Emmanuel | C5: Emmanuel | D5: ← Escribe aquí el día 1
A6: Nómina esposa | C6: Esposa | D6: ← Escribe aquí el día 1
A7: TOTAL INGRESOS | B7: =SUM(B5:B6) -> 0
A9: GASTOS DEL MES
A10: Concepto | B10: Importe (€) | C10: Quién | D10: Notas
A11: Artal viaje Suiza | B11: 169 | C11: Familia
A12: Morabanc 4/24 | B12: 292 | C12: Familia
A13: Universidad 6/12 TDC | B13: 266 | C13: Emmanuel
A14: Piso | B14: 887 | C14: Familia
A15: Dacia 6/60 | B15: 337 | C15: Familia
A16: Trastero | B16: 127 | C16: Familia
A17: FEDA | B17: 137 | C17: Familia
A18: Telecom Andorra | B18: 100 | C18: Familia
A19: Credit baja Elisel | B19: 30 | C19: Esposa
A20: Credit baja Emmanuel | B20: 17 | C20: Emmanuel
A21: Parking | B21: 85 | C21: Familia
A22: Becier 5/6 | B22: 116 | C22: Familia
... A26: Creand salud | B26: 96.58 | C26: Familia
A32: TOTAL GASTOS | B32: =SUM(B11:B31) -> 3606.58
A34: RESUMEN DEL MES
A35: Total ingresos | B35: =B7 -> 0
A36: Total gastos | B36: =B32 -> 3606.58
A37: AHORRO DEL MES | B37: =B35-B36 -> -3606.58

Sheet Septiembre 2025
A1: Control Financiero — Septiembre 2025
A3: INGRESOS DEL MES
A4: Concepto | B4: Importe (€) | C4: Quién | D4: Notas
A5: Nómina Emmanuel | C5: Emmanuel | D5: ← Escribe aquí el día 1
A6: Nómina esposa | C6: Esposa | D6: ← Escribe aquí el día 1
A7: TOTAL INGRESOS | B7: =SUM(B5:B6) -> 0
A9: GASTOS DEL MES
A10: Concepto | B10: Importe (€) | C10: Quién | D10: Notas
A11: Morabanc 5/24 | B11: 292 | C11: Familia | D11: cumpleaños Emilia
A12: Cantina | B12: 190 | C12: Emmanuel
A13: Actividad APACEF | B13: 42 | C13: Familia
A14: Universidad | B14: 266 | C14: Emmanuel
A15: Dacia 7/60 | B15: 337 | C15: Familia
A16: Piso | B16: 887 | C16: Familia
A17: Trastero | B17: 127 | C17: Familia
A18: FEDA | B18: 880 | C18: Familia | D18: revisar
A19: Telecom Andorra | B19: 102 | C19: Familia
A20: Credit baja Elisel | B20: 30 | C20: Esposa
A21: Credit baja Emmanuel | B21: 17 | C21: Emmanuel
A22: Parking | B22: 85 | C22: Familia
A23: Netflix | B23: 13 | C23: Familia
A24: Peaje Suiza | B24: 150 | C24: Familia
A25: Creand salud | B25: 96 | C25: Familia
A26: Becier 6/6 | B26: 116 | C26: Familia
A27: Foc i lloc | B27: 105 | C27: Familia
A28: Inlingua mes 1 | B28: 146 | C28: Emmanuel
A29: Artal | B29: 319 | C29: Familia
A30: Matrícula maternal Inlingua | B30: 144 | C30: Familia
... A32: SAAS comedor | B32: 39.5 | C32: Familia
A38: TOTAL GASTOS | B38: =SUM(B11:B37) -> 4411
A40: RESUMEN DEL MES
A41: Total ingresos | B41: =B7 -> 0
A42: Total gastos | B42: =B38 -> 4411
A43: AHORRO DEL MES | B43: =B41-B42 -> -4411

Sheet Octubre 2025
A1: Control Financiero — Octubre 2025
A3: INGRESOS DEL MES
A4: Concepto | B4: Importe (€) | C4: Quién | D4: Notas
A5: Nómina Emmanuel | C5: Emmanuel | D5: ← Escribe aquí el día 1
A6: Nómina esposa | C6: Esposa | D6: ← Escribe aquí el día 1
A7: TOTAL INGRESOS | B7: =SUM(B5:B6) -> 0
A9: GASTOS DEL MES
A10: Concepto | B10: Importe (€) | C10: Quién | D10: Notas
A11: Morabanc 6/24 | B11: 292 | C11: Familia | D11: viaje Corea Sur
A12: Cantina | B12: 190 | C12: Emmanuel
A13: Actividad APACEF | B13: 92 | C13: Familia
A14: Universidad | B14: 266 | C14: Emmanuel
A15: Dacia 8/60 | B15: 337 | C15: Familia
A16: Piso | B16: 887 | C16: Familia
A17: Trastero | B17: 127 | C17: Familia
A18: FEDA | B18: 96.31 | C18: Familia
A19: Telecom Andorra | B19: 100 | C19: Familia
A20: Credit baja Elisel | B20: 30 | C20: Esposa
A21: Credit baja Emmanuel | B21: 17 | C21: Emmanuel
A22: Parking | B22: 85 | C22: Familia
A23: Netflix | B23: 13 | C23: Familia
A24: Cuota APACEF anual | B24: 30 | C24: Familia | D24: 29/10
A25: Creand salud | B25: 96 | C25: Familia
A26: Inlingua Emmanuel | B26: 146 | C26: Emmanuel
A27: Artal | B27: 420 | C27: Familia
A33: TOTAL GASTOS | B33: =SUM(B11:B32) -> 3224.31
A35: RESUMEN DEL MES
A36: Total ingresos | B36: =B7 -> 0
A37: Total gastos | B37: =B33 -> 3224.31
A38: AHORRO DEL MES | B38: =B36-B37 -> -3224.31

Sheet Noviembre 2025
A1: Control Financiero — Noviembre 2025
A3: INGRESOS DEL MES
A4: Concepto | B4: Importe (€) | C4: Quién | D4: Notas
A5: Nómina Emmanuel | C5: Emmanuel | D5: ← Escribe aquí el día 1
A6: Nómina esposa | C6: Esposa | D6: ← Escribe aquí el día 1
A7: TOTAL INGRESOS | B7: =SUM(B5:B6) -> 0
A9: GASTOS DEL MES
A10: Concepto | B10: Importe (€) | C10: Quién | D10: Notas
A11: Morabanc 7/24 | B11: 292 | C11: Familia
A12: Cantina | B12: 190 | C12: Emmanuel
A13: Actividad APACEF | B13: 92 | C13: Familia
A14: Universidad | B14: 266 | C14: Emmanuel
A15: Dacia 9/60 | B15: 337 | C15: Familia
A16: Piso | B16: 887 | C16: Familia
A17: Trastero | B17: 127 | C17: Familia
A18: FEDA | B18: 77.33 | C18: Familia
A19: Telecom Andorra | B19: 100 | C19: Familia
A20: Credit baja Elisel | B20: 30 | C20: Esposa
A21: Credit baja Emmanuel | B21: 17 | C21: Emmanuel
A22: Parking | B22: 85 | C22: Familia
... A29: Toner Negro HP | B29: 120 | C29: Familia
A35: TOTAL GASTOS | B35: =SUM(B11:B34) -> 3254.13
A37: RESUMEN DEL MES
A38: Total ingresos | B38: =B7 -> 0
A39: Total gastos | B39: =B35 -> 3254.13
A40: AHORRO DEL MES | B40: =B38-B39 -> -3254.13

Sheet Diciembre 2025
A1: Control Financiero — Diciembre 2025
A3: INGRESOS DEL MES
A4: Concepto | B4: Importe (€) | C4: Quién | D4: Notas
A5: Nómina Emmanuel | C5: Emmanuel | D5: ← Escribe aquí el día 1
A6: Nómina esposa | C6: Esposa | D6: ← Escribe aquí el día 1
A7: TOTAL INGRESOS | B7: =SUM(B5:B6) -> 0
A9: GASTOS DEL MES
A10: Concepto | B10: Importe (€) | C10: Quién | D10: Notas
A11: Morabanc 8/24 | B11: 292 | C11: Familia
A12: Cantina | B12: 790 | C12: Familia
A13: Actividad APACEF | B13: 100 | C13: Familia
A14: Universidad | B14: 266 | C14: Emmanuel
A15: Dacia 10/60 | B15: 337 | C15: Familia
A16: Basque | B16: 337.75 | C16: Familia
A17: Piso | B17: 887 | C17: Familia
A18: Trastero | B18: 127 | C18: Familia
A19: FEDA | B19: 193 | C19: Familia
A20: Telecom Andorra | B20: 100 | C20: Familia
A21: Baja Elisel | B21: 30 | C21: Esposa
A22: Baja Emmanuel | B22: 17 | C22: Emmanuel
... A32: Moto mantenimiento | B32: 142 | C32: Emmanuel
A38: TOTAL GASTOS | B38: =SUM(B11:B37) -> 5426.75
A40: RESUMEN DEL MES
A41: Total ingresos | B41: =B7 -> 0
A42: Total gastos | B42: =B38 -> 5426.75
A43: AHORRO DEL MES | B43: =B41-B42 -> -5426.75

Sheet Enero 2026
A1: Control Financiero — Enero 2026
A3: INGRESOS DEL MES
A4: Concepto | B4: Importe (€) | C4: Quién | D4: Notas
A5: Nómina Emmanuel | C5: Emmanuel | D5: ← Escribe aquí el día 1
A6: Nómina esposa | C6: Esposa | D6: ← Escribe aquí el día 1
A7: TOTAL INGRESOS | B7: =SUM(B5:B6) -> 0
A9: GASTOS DEL MES
A10: Concepto | B10: Importe (€) | C10: Quién | D10: Notas
A11: Microsoft mensual | B11: 7 | C11: Emmanuel | D11: 11 enero
A12: Morabanc 9/24 | B12: 292 | C12: Familia
A13: Cantina | B13: 790 | C13: Familia
A14: Actividad APACEF | B14: 92 | C14: Familia
A15: Universidad | B15: 266 | C15: Emmanuel
A16: Dacia 11/60 | B16: 337 | C16: Familia
A17: Piso | B17: 887 | C17: Familia
A18: Trastero | B18: 127 | C18: Familia
A19: Telecom Andorra | B19: 100 | C19: Familia
A20: FEDA | B20: 200 | C20: Familia
A21: Parking | B21: 85 | C21: Familia
A22: Netflix | B22: 14 | C22: Familia
A23: Inlingua | B23: 146 | C23: Emmanuel
... A28: Rodisnet | B28: 91 | C28: Familia
A34: TOTAL GASTOS | B34: =SUM(B11:B33) -> 3906
A36: RESUMEN DEL MES
A37: Total ingresos | B37: =B7 -> 0
A38: Total gastos | B38: =B34 -> 3906
A39: AHORRO DEL MES | B39: =B37-B38 -> -3906

Sheet Febrero 2026
A1: Control Financiero — Febrero 2026
A3: INGRESOS DEL MES
A4: Concepto | B4: Importe (€) | C4: Quién | D4: Notas
A5: Nómina Emmanuel | C5: Emmanuel | D5: ← Escribe aquí el día 1
A6: Nómina esposa | C6: Esposa | D6: ← Escribe aquí el día 1
A7: TOTAL INGRESOS | B7: =SUM(B5:B6) -> 0
A9: GASTOS DEL MES
A10: Concepto | B10: Importe (€) | C10: Quién | D10: Notas
A11: Microsoft mensual | B11: 7 | C11: Emmanuel | D11: 11 febrero
A12: Póliza Dacia anual | B12: 674 | C12: Familia | D12: 11/02/26
A13: Morabanc 10/24 | B13: 292 | C13: Familia
A14: Cantina | B14: 140 | C14: Emmanuel
A15: Actividad APACEF | B15: 92 | C15: Familia
A16: Universidad | B16: 266 | C16: Emmanuel
A17: Dacia 12/60 | B17: 337 | C17: Familia
A18: Piso | B18: 865 | C18: Familia
A19: Trastero | B19: 127 | C19: Familia
A20: Telecom Andorra | B20: 100 | C20: Familia
A21: FEDA | B21: 213 | C21: Familia
A22: Parking | B22: 88 | C22: Familia
A23: Netflix | B23: 14 | C23: Familia
A24: Inlingua | B24: 146 | C24: Emmanuel
... A31: 4Health anual | B31: 35 | C31: Familia
A37: TOTAL GASTOS | B37: =SUM(B11:B36) -> 5073
A39: RESUMEN DEL MES
A40: Total ingresos | B40: =B7 -> 0
A41: Total gastos | B41: =B37 -> 5073
A42: AHORRO DEL MES | B42: =B40-B41 -> -5073

Sheet Marzo 2026
A1: Control Financiero — Marzo 2026
A3: INGRESOS DEL MES
A4: Concepto | B4: Importe (€) | C4: Quién | D4: Notas
A5: Nómina Emmanuel | C5: Emmanuel | D5: ← Escribe aquí el día 1
A6: Nómina esposa | C6: Esposa | D6: ← Escribe aquí el día 1
A7: TOTAL INGRESOS | B7: =SUM(B5:B6) -> 0
A9: GASTOS DEL MES
A10: Concepto | B10: Importe (€) | C10: Quién | D10: Notas
A11: Microsoft | B11: 7 | C11: Emmanuel
A12: Morabanc 11/24 | B12: 292 | C12: Familia
A13: Morabanc Dacia 13/60 | B13: 337 | C13: Familia
A14: Cantina | B14: 190 | C14: Emmanuel
A15: Actividad APACEF | B15: 92 | C15: Familia
A16: Piso | B16: 910 | C16: Familia
A17: Trastero | B17: 127 | C17: Familia
A18: Telecom Andorra | B18: 100 | C18: Familia
A19: FEDA | B19: 200 | C19: Familia
A20: Parking | B20: 88 | C20: Familia
A21: Netflix | B21: 14 | C21: Familia
A22: Inlingua | B22: 146 | C22: Emmanuel
... A26: Artal | B26: 77 | C26: Familia
A32: TOTAL GASTOS | B32: =SUM(B11:B31) -> 2837
A34: RESUMEN DEL MES
A35: Total ingresos | B35: =B7 -> 0
A36: Total gastos | B36: =B32 -> 2837
A37: AHORRO DEL MES | B37: =B35-B36 -> -2837

Sheet Abril 2026
A1: Control Financiero — Abril 2026
A3: INGRESOS DEL MES
A4: Concepto | B4: Importe (€) | C4: Quién | D4: Notas
A5: Nómina Emmanuel | C5: Emmanuel | D5: ← Escribe aquí el día 1
A6: Nómina esposa | C6: Esposa | D6: ← Escribe aquí el día 1
A7: TOTAL INGRESOS | B7: =SUM(B5:B6) -> 0
A9: GASTOS DEL MES
A10: Concepto | B10: Importe (€) | C10: Quién | D10: Notas
A11: Microsoft | B11: 7 | C11: Emmanuel
A12: Morabanc 12/24 | B12: 292 | C12: Familia
A13: Morabanc Dacia 14/60 | B13: 337 | C13: Familia
A14: Cantina | B14: 190 | C14: Emmanuel
A15: Actividad APACEF | B15: 92 | C15: Familia
A16: Piso | B16: 910 | C16: Familia
A17: Trastero | B17: 127 | C17: Familia
A18: Telecom Andorra | B18: 100 | C18: Familia
A19: FEDA | B19: 150 | C19: Familia
A20: Parking | B20: 88 | C20: Familia
A21: Netflix | B21: 14 | C21: Familia
A22: Inlingua | B22: 146 | C22: Emmanuel
... A24: Crem Salud complementaria | B24: 105 | C24: Familia
A30: TOTAL GASTOS | B30: =SUM(B11:B29) -> 2620
A32: RESUMEN DEL MES
A33: Total ingresos | B33: =B7 -> 0
A34: Total gastos | B34: =B30 -> 2620
A35: AHORRO DEL MES | B35: =B33-B34 -> -2620

Sheet Mayo 2026
A1: Control Financiero — Mayo 2026
A3: INGRESOS DEL MES
A4: Concepto | B4: Importe (€) | C4: Quién | D4: Notas
A5: Nómina Emmanuel | C5: Emmanuel | D5: ← Escribe aquí el día 1
A6: Nómina esposa | C6: Esposa | D6: ← Escribe aquí el día 1
A7: TOTAL INGRESOS | B7: =SUM(B5:B6) -> 0
A9: GASTOS DEL MES
A10: Concepto | B10: Importe (€) | C10: Quién | D10: Notas
A11: Morabanc nuevo 1/24 | B11: 553 | C11: Familia
A12: Morabanc Dacia 15/60 | B12: 337 | C12: Familia
A18: TOTAL GASTOS | B18: =SUM(B11:B17) -> 890
A20: RESUMEN DEL MES
A21: Total ingresos | B21: =B7 -> 0
A22: Total gastos | B22: =B18 -> 890
A23: AHORRO DEL MES | B23: =B21-B22 -> -890

Sheet Histórico anual
A1: Histórico anual — gastos totales por mes
A2: Año | B2: Ene | C2: Feb | D2: Mar | E2: Abr | F2: May | G2: Jun | H2: Jul | I2: Ago | J2: Sep | K2: Oct | L2: Nov | M2: Dic | N2: TOTAL AÑO
A3: 2022 | B3: - | C3: - | D3: - | E3: - | F3: - | G3: - | H3: - | I3: - | J3: - | K3: - | L3: ='Noviembre 2022'!B40 -> 3087.37 | M3: ='Diciembre 2022'!B37 -> 2690.48 | N3: =SUM(B3:M3) -> 5777.85
A4: 2023 | B4: ='Enero 2023'!B43 -> 3090.12 | C4: ='Febrero 2023'!B44 -> 3206.23 | D4: ='Marzo 2023'!B45 -> 3186.62 | E4: ='Abril 2023'!B44 -> 3196.99 | F4: ='Mayo 2023'!B47 -> 3453.63 | G4: ='Junio 2023'!B48 -> 3079.04 | H4: ='Julio 2023'!B48 -> 3284.64 | I4: ='Agosto 2023'!B48 -> 4071.14 | J4: ='Septiembre 2023'!B50 -> 3691.67 | K4: ='Octubre 2023'!B57 -> 4493.53 | L4: ='Noviembre 2023'!B53 -> 3687.35 | M4: ='Diciembre 2023'!B53 -> 3972.16 | N4: =SUM(B4:M4) -> 42413.12
A5: 2024 | B5: ='Enero 2024'!B53 -> 4463.68 | C5: ='Febrero 2024'!B52 -> 4785.5 | D5: ='Marzo 2024'!B48 -> 4997.31 | E5: ='Abril 2024'!B44 -> 3892 | F5: ='Mayo 2024'!B45 -> 4233.26 | G5: ='Junio 2024'!B48 -> 4000.27 | H5: ='Julio 2024'!B46 -> 4269.7 | I5: ='Agosto 2024'!B43 -> 3734.13 | J5: ='Septiembre 2024'!B46 -> 4380.06 | K5: ='Octubre 2024'!B43 -> 4262.95 | L5: ='Noviembre 2024'!B43 -> 4025.25 | M5: ='Diciembre 2024'!B41 -> 3418.72 | N5: =SUM(B5:M5) -> 50462.83
A6: 2025 | B6: ='Enero 2025'!B41 -> 4056.89 | C6: ='Febrero 2025'!B39 -> 3889.19 | D6: ='Marzo 2025'!B35 -> 3603.37 | E6: ='Abril 2025'!B40 -> 3665.73 | F6: ='Mayo 2025'!B34 -> 3820.58 | G6: ='Junio 2025'!B37 -> 3544.09 | H6: ='Julio 2025'!B34 -> 3914.86 | I6: ='Agosto 2025'!B32 -> 3606.58 | J6: ='Septiembre 2025'!B38 -> 4411 | K6: ='Octubre 2025'!B33 -> 3224.31 | L6: ='Noviembre 2025'!B35 -> 3254.13 | M6: ='Diciembre 2025'!B38 -> 5426.75 | N6: =SUM(B6:M6) -> 46417.48
A7: 2026 | B7: ='Enero 2026'!B34 -> 3906 | C7: ='Febrero 2026'!B37 -> 5073 | D7: ='Marzo 2026'!B32 -> 2837 | E7: ='Abril 2026'!B30 -> 2620 | F7: ='Mayo 2026'!B18 -> 890 | G7: - | H7: - | I7: - | J7: - | K7: - | L7: - | M7: - | N7: =SUM(B7:M7) -> 15326
A9: Año | B9: Ene | C9: Feb | D9: Mar | E9: Abr | F9: May | G9: Jun | H9: Jul | I9: Ago | J9: Sep | K9: Oct | L9: Nov | M9: Dic | N9: AHORRO AÑO
A10: 2022 | B10: - | C10: - | D10: - | E10: - | F10: - | G10: - | H10: - | I10: - | J10: - | K10: - | L10: ='Noviembre 2022'!B45 -> -3087.37 | M10: ='Diciembre 2022'!B42 -> -2690.48 | N10: =SUM(B10:M10) -> -5777.85
A11: 2023 | B11: ='Enero 2023'!B48 -> -3090.12 | C11: ='Febrero 2023'!B49 -> -3206.23 | D11: ='Marzo 2023'!B50 -> -3186.62 | E11: ='Abril 2023'!B49 -> -3196.99 | F11: ='Mayo 2023'!B52 -> -3453.63 | G11: ='Junio 2023'!B53 -> -3079.04 | H11: ='Julio 2023'!B53 -> -3284.64 | I11: ='Agosto 2023'!B53 -> -4071.14 | J11: ='Septiembre 2023'!B55 -> -3691.67 | K11: ='Octubre 2023'!B62 -> -4493.53 | L11: ='Noviembre 2023'!B58 -> -3687.35 | M11: ='Diciembre 2023'!B58 -> -3972.16 | N11: =SUM(B11:M11) -> -42413.12
A12: 2024 | B12: ='Enero 2024'!B58 -> -4463.68 | C12: ='Febrero 2024'!B57 -> -4785.5 | D12: ='Marzo 2024'!B53 -> -4997.31 | E12: ='Abril 2024'!B49 -> -3892 | F12: ='Mayo 2024'!B50 -> -4233.26 | G12: ='Junio 2024'!B53 -> -4000.27 | H12: ='Julio 2024'!B51 -> -4269.7 | I12: ='Agosto 2024'!B48 -> -3734.13 | J12: ='Septiembre 2024'!B51 -> -4380.06 | K12: ='Octubre 2024'!B48 -> -4262.95 | L12: ='Noviembre 2024'!B48 -> -4025.25 | M12: ='Diciembre 2024'!B46 -> -3418.72 | N12: =SUM(B12:M12) -> -50462.83
A13: 2025 | B13: ='Enero 2025'!B46 -> -4056.89 | C13: ='Febrero 2025'!B44 -> -3889.19 | D13: ='Marzo 2025'!B40 -> -3603.37 | E13: ='Abril 2025'!B45 -> -3665.73 | F13: ='Mayo 2025'!B39 -> -3820.58 | G13: ='Junio 2025'!B42 -> -3544.09 | H13: ='Julio 2025'!B39 -> -3914.86 | I13: ='Agosto 2025'!B37 -> -3606.58 | J13: ='Septiembre 2025'!B43 -> -4411 | K13: ='Octubre 2025'!B38 -> -3224.31 | L13: ='Noviembre 2025'!B40 -> -3254.13 | M13: ='Diciembre 2025'!B43 -> -5426.75 | N13: =SUM(B13:M13) -> -46417.48
A14: 2026 | B14: ='Enero 2026'!B39 -> -3906 | C14: ='Febrero 2026'!B42 -> -5073 | D14: ='Marzo 2026'!B37 -> -2837 | E14: ='Abril 2026'!B35 -> -2620 | F14: ='Mayo 2026'!B23 -> -890 | G14: - | H14: - | I14: - | J14: - | K14: - | L14: - | M14: - | N14: =SUM(B14:M14) -> -15326

Sheet Recordatorios
A1: Recordatorios — pagos próximos
A2: Concepto | B2: Importe | C2: Fecha | D2: Quién | E2: Estado
A3: Morabanc cuota préstamo | B3: 292 | C3: 1 mayo 2026 | D3: Familia | E3: Pendiente
A4: Morabanc Dacia | B4: 337 | C4: 1 mayo 2026 | D4: Familia | E4: Pendiente
A5: Piso | B5: 910 | C5: 1 mayo 2026 | D5: Familia | E5: Pendiente
A6: Telecom Andorra | B6: 100 | C6: 1 mayo 2026 | D6: Familia | E6: Pendiente
A7: Universidad | B7: 266 | C7: 1 mayo 2026 | D7: Emmanuel | E7: Pendiente
A8: Netflix | B8: 14 | C8: 1 mayo 2026 | D8: Familia | E8: Pendiente
A9: Inlingua | B9: 146 | C9: 1 mayo 2026 | D9: Emmanuel | E9: Pendiente
A10: Crem Salud | B10: 105 | C10: 1 mayo 2026 | D10: Familia | E10: Pendiente
A11: Microsoft mensual | B11: 7 | C11: 11 junio 2026 | D11: Emmanuel | E11: Pendiente

Sheet Como usar
A1: Como usar este archivo
A2: Como registrar las nóminas cada mes
A3: El día 1 de cada mes, abre la hoja del mes (ej: 'Mayo 2026'). Las celdas azules en las filas 5 y 6 son para escribir la nómina de Emmanuel y la de tu esposa. El total de ingresos y el ahorro se calculan solos.
A5: Como añadir gastos
A6: Baja a la sección 'GASTOS DEL MES'. Hay filas vacías al final para añadir nuevos gastos. Escribe el concepto, el importe y quién pagó. El total y el ahorro se actualizan solos.
A8: Como crear el mes siguiente
A9: Click derecho en la pestaña del mes actual → Mover o copiar → marcar 'Crear copia'. Borra los importes variables y las nóminas (las celdas azules). Los gastos fijos que se repiten puedes dejarlos.
A11: Subir a Google Drive
